2021-07-26 23:28:11:     Reconnected successfully!
2021-07-26 23:28:11:     Game type = "Red bonus tile" : True, "Open tanyao" : True, "Game  length" : tonpusen
2021-07-26 23:28:12:     Reconnected. Resuming game state...
2021-07-26 23:28:12:     --------------------------------------------------
2021-07-26 23:28:12:     Round number:1, Honba sticks:1, Bonus tile indicator:🀆
2021-07-26 23:28:12:     Players: [MyBot - 新人 - 22000, nanow - 初段 - 21000, いも詰め合わせ - 初段 - 30000, kazki - 二段 - 27000]
2021-07-26 23:28:12:     Dealer: いも詰め合わせ - 初段 - 30000
2021-07-26 23:28:12:     Round  wind: 🀀
2021-07-26 23:28:12:     Player wind: 🀂
2021-07-26 23:28:12:  
2021-07-26 23:28:13:     [Player 2] discards: 🀁🀘🀐🀆🀋 + 🀔
2021-07-26 23:28:13:     [Player 3] draws a tile...
2021-07-26 23:28:20:     [Player 3] discards: 🀃🀕🀖🀀🀀🀏 + 🀠
2021-07-26 23:28:20: 
2021-07-26 23:28:20:     [Bot] draws a tile: 🀇🀈🀊🀊🀎🀏🀚🀜🀝🀒🀔🀁🀃 + 🀟
2021-07-26 23:28:20: Unexpected exception
Traceback (most recent call last):
  File "c:\Users\chenq\Desktop\Mahjong\Mahjong AI\MahjongAI\main.py", line 17, in connect_and_play
    return client.start_game()
  File "c:\Users\chenq\Desktop\Mahjong\Mahjong AI\MahjongAI\client\tenhou_client.py", line 129, in start_game
    if self._handle_draw_tile(msg):
  File "c:\Users\chenq\Desktop\Mahjong\Mahjong AI\MahjongAI\client\tenhou_client.py", line 535, in _handle_draw_tile
    self.game_table.bot.tiles136.remove(discard_tile_136)
ValueError: list.remove(x): x not in list
2021-07-26 23:28:20: End the game...
2021-07-26 23:28:20:     Game was ended unexpected
2021-07-26 23:28:20: 
